{
 "cells": [
  {
   "cell_type": "markdown",
   "id": "7c6d5656",
   "metadata": {},
   "source": [
    "Q1. Describe three applications for exception processing."
   ]
  },
  {
   "cell_type": "markdown",
   "id": "37fe61ac",
   "metadata": {},
   "source": [
    "Exception processing is an important feature of programming languages like Python that allows developers to gracefully handle errors and unexpected situations that can occur during program execution. Here are three applications of exception processing:\n",
    "\n",
    "Error handling: One of the most common applications of exception processing is to handle errors that occur during program execution. For example, if a program tries to open a file that doesn't exist, it can raise a FileNotFoundError exception. By catching this exception and handling it appropriately, the program can continue to execute without crashing or behaving unpredictably.\n",
    "\n",
    "Resource management: Another application of exception processing is to manage resources such as files, network connections, and database connections. If a program fails to properly close a resource after using it, it can cause problems such as memory leaks or resource exhaustion. By using a try-finally block, the program can ensure that the resource is properly closed, even if an exception is raised during program execution.\n",
    "\n",
    "Program flow control: Exception processing can also be used to control the flow of a program. For example, a program might raise an exception to signal that a particular condition has occurred, and then catch the exception to perform some special handling or take a different branch of the program. This can be useful for implementing complex control flows in programs, such as state machines or event-driven systems.\n",
    "\n"
   ]
  },
  {
   "cell_type": "markdown",
   "id": "54f181c1",
   "metadata": {},
   "source": [
    "\n",
    "\n",
    "Q2. What happens if you don't do something extra to treat an exception?\n"
   ]
  },
  {
   "cell_type": "markdown",
   "id": "38ef1cb5",
   "metadata": {},
   "source": [
    "If an exception is raised in a Python program and you don't handle it using exception processing, the program will terminate and print a traceback message that shows where the exception occurred and what type of exception was raised. This can make it difficult to diagnose and fix the problem that caused the exception, and can lead to unexpected behavior or crashes in the program.\n",
    "\n",
    "In addition, failing to handle exceptions can lead to security vulnerabilities in programs, since unhandled exceptions can expose sensitive information or allow attackers to take control of the program.\n",
    "\n",
    "To handle exceptions in Python, you can use a try-except block to catch specific types of exceptions and handle them appropriately. By catching and handling exceptions, you can gracefully recover from errors and prevent your program from crashing or behaving unpredictably."
   ]
  },
  {
   "cell_type": "markdown",
   "id": "1609bb1e",
   "metadata": {},
   "source": [
    "\n",
    "Q3. What are your options for recovering from an exception in your script?\n"
   ]
  },
  {
   "cell_type": "markdown",
   "id": "d71aeda3",
   "metadata": {},
   "source": [
    "When an exception is raised in a Python script, there are several options for recovering from the exception and continuing execution of the script:\n",
    "\n",
    "Catch and handle the exception: One option is to catch the exception using a try-except block and handle it appropriately. For example, you might print an error message or take some other action to recover from the error and continue execution of the script.\n",
    "\n",
    "Retry the operation: If the exception was caused by a temporary error such as a network timeout, you might be able to recover by retrying the operation that caused the exception. For example, you might retry a failed network request several times before giving up and reporting an error.\n",
    "\n",
    "Gracefully exit the script: In some cases, it may not be possible to recover from an exception, or it may not make sense to continue executing the script. In this case, you can use the sys.exit() function to gracefully exit the script with a specified exit code.\n",
    "\n",
    "Raise a different exception: In some cases, you may want to raise a different exception to indicate that the original operation failed. For example, you might catch an exception raised by a third-party library and raise a custom exception that provides more specific information about the error."
   ]
  },
  {
   "cell_type": "markdown",
   "id": "33e5ebbc",
   "metadata": {},
   "source": [
    "\n",
    "\n",
    "Q4. Describe two methods for triggering exceptions in your script.\n"
   ]
  },
  {
   "cell_type": "markdown",
   "id": "c16cbeeb",
   "metadata": {},
   "source": [
    "Using the raise statement: You can use the raise statement to manually trigger an exception in your script. The raise statement takes an exception type as an argument and can also include an optional error message. For example, the following code raises a ValueError exception with a custom error message:\n",
    "\n",
    "x = -5\n",
    "if x < 0:\n",
    "    raise ValueError(\"x must be non-negative\")\n",
    "    \n",
    "When this code is executed, it will raise a ValueError exception with the message \"x must be non-negative\".\n",
    "\n",
    "Using built-in functions: Many built-in functions in Python can raise exceptions if they encounter an error. For example, the open() function can raise a FileNotFoundError if the specified file does not exist, or a PermissionError if the user does not have permission to open the file. Similarly, the int() function can raise a ValueError if it is passed an invalid integer string.\n",
    "\n",
    "Here is an example of triggering an exception using the open() function:\n",
    "try:\n",
    "    with open(\"nonexistent_file.txt\", \"r\") as f:\n",
    "        contents = f.read()\n",
    "except FileNotFoundError:\n",
    "    print(\"The file does not exist\")\n",
    "    \n",
    "    \n",
    "In this code, the open() function is called with a filename that does not exist, which triggers a FileNotFoundError. The exception is caught using a try-except block, and the program prints a custom error message instead of crashing."
   ]
  },
  {
   "cell_type": "markdown",
   "id": "8781fcad",
   "metadata": {},
   "source": [
    "Q5. Identify two methods for specifying actions to be executed at termination time, regardless of whether or not an exception exists."
   ]
  },
  {
   "cell_type": "markdown",
   "id": "03a0300e",
   "metadata": {},
   "source": [
    "Using a finally block: You can use a finally block to specify code that should be executed at the end of a try-except block, regardless of whether or not an exception was raised. For example, the following code opens a file, reads its contents, and closes the file in a finally block:\n",
    "\n",
    "try:\n",
    "    f = open(\"myfile.txt\")\n",
    "    contents = f.read()\n",
    "except FileNotFoundError:\n",
    "    print(\"The file does not exist\")\n",
    "finally:\n",
    "    f.close()\n",
    "\n",
    "\n",
    "In this code, the open() function is called to open the file, and its contents are read. If the file does not exist, a custom error message is printed. Finally, the close() method is called on the file object, ensuring that it is closed regardless of whether or not an exception was raised.\n",
    "\n",
    "Using the atexit module: The atexit module provides a way to register functions to be called when a Python script exits, regardless of whether or not an exception was raised. To register a function, you can use the atexit.register() function. For example, the following code registers a function to be called when the script exits:\n",
    "\n",
    "import atexit\n",
    "\n",
    "def goodbye():\n",
    "    print(\"Goodbye, world!\")\n",
    "\n",
    "atexit.register(goodbye)\n",
    "\n",
    "In this code, the goodbye() function is registered using the atexit.register() function. When the script exits, the goodbye() function will be called, printing \"Goodbye, world!\" to the console."
   ]
  },
  {
   "cell_type": "code",
   "execution_count": null,
   "id": "a7957325",
   "metadata": {},
   "outputs": [],
   "source": []
  }
 ],
 "metadata": {
  "kernelspec": {
   "display_name": "Python 3 (ipykernel)",
   "language": "python",
   "name": "python3"
  },
  "language_info": {
   "codemirror_mode": {
    "name": "ipython",
    "version": 3
   },
   "file_extension": ".py",
   "mimetype": "text/x-python",
   "name": "python",
   "nbconvert_exporter": "python",
   "pygments_lexer": "ipython3",
   "version": "3.10.9"
  }
 },
 "nbformat": 4,
 "nbformat_minor": 5
}
